Workbook
Name Empresa: #REF!
Name Empresas: #REF!
Name Empresas: #REF!
Name Empresas: #REF!
Name Empresas: #REF!

Sheet Listas
A1: distribuidoras | C1: rubros_spee | E1: rubros_sapg | G1: etapas_funcionales_spee | I1: sub_etapas_funcionales_spee | K1: tipo_gasto | M1: grupo_gasto | O1: fuente | Q1: servicios | S1: fecha_corte | T1: fecha_entrega | V1: tipo_proyecto | X1: estado_proyecto | Z1: etapa_ejecucion_proyecto | AB1: tipo_permiso_ambiental
A2: CNEL EP Eficiencia Energética | C2: Calidad | E2: Calidad | G2: Subtransmisión | I2: Lineas de Subtransmisión | K2: Gastos administrativos | M2: Materiales | O2: PLANREP Crédito | Q2: SPEE | S2: Al 31 de mayo de 2026 | T2: 46198 | V2: Mejora | X2: No iniciado | Z2: No iniciado 0% | AB2: Licencia Ambiental
A3: CNEL EP Oficina Central | C3: Responsabilidad Ambiental | E3: Otros | G3: Distribución | I3: S/E de Distribución | K3: Gastos de venta | M3: Mano de Obra | O3: PMD Crédito | Q3: SAPG | S3: Al 30 de junio de 2026 | T3: 46218 | V3: Repotenciación | X3: Iniciado | Z3: Elaboración de pliegos 5% | AB3: Certificado Ambiental
A4: CNEL EP UN Bolívar | C4: SIGDE | G4: Administración | I4: Alimentadores Primarios | K4: Gastos financieros | M4: Servicios | O4: PMD BID I | Q4: SCVE | S4: Al 31 de julio de 2026 | T4: 46251 | V4: Reposición | X4: Finalizado | Z4: Disponibilidad de pliegos 10% | AB4: Registro Ambiental
A5: CNEL EP UN El Oro | C5: Confiabilidad | G5: Comercialización | I5: Transformadores de Distribución | M5: Otros gastos | O5: PMD BID II | S5: Al 31 de agosto de 2026 | T5: 46280 | V5: Responsabilidad Ambiental | X5: Paralizado | Z5: Publicación del proceso 15% | AB5: No aplica
A6: CNEL EP UN Esmeraldas | C6: Otros | G6: Instalaciones de Servicio al Cliente | I6: Red Secundaria | O6: PMD BID III | S6: Al 30 de septiembre de 2026 | T6: 46310 | Z6: Resolución de adjudicación 30%
A7: CNEL EP UN Guayaquil | I7: Acometidas y Medidores | O7: PMD CAF | S7: Al 31 de octubre de 2026 | T7: 46342 | Z7: Adjudicación y firma de contrato 40%
A8: CNEL EP UN Guayas Los Ríos | I8: Comercialización | O8: PMD AFD | S8: Al 30 de noviembre de 2026 | T8: 46371 | Z8: En ejecución 41% - 90%
A9: CNEL EP UN Los Ríos | O9: PMD BID V | S9: Al 31 de diciembre de 2026 - Preliminar | T9: 46402 | Z9: Acta de entrega - recepción 95%
A10: CNEL EP UN Manabí | O10: FERUM | S10: Al 31 de diciembre de 2026 - Definitivo | T10: 46461 | Z10: Registro contable 100%
A11: CNEL EP UN Milagro | O11: FERUM BID II
A12: CNEL EP UN Santa Elena | O12: FERUM BID III
A13: CNEL EP UN Santo Domingo | O13: FERUM BID V
A14: CNEL EP UN Sucumbíos | O14: PRIZA
A15: EE Ambato | O15: PMD Fiscales
A16: EE Azogues | O16: FERUM Fiscales
A17: EE Centro Sur | O17: BID I
A18: EE Cotopaxi | O18: BID II
A19: EE Galápagos | O19: BIDIII
A20: EE Norte | O20: BID IV
A21: EE Quito | O21: BID V
A22: EE Riobamba | O22: BID VI
A23: EE Sur | O23: Otras Inversiones y Convenios
O24: Aportes de accionistas
O25: Contribuciones de usuarios

Sheet Recursos aprobados
A1: distribuidora | B1: año | C1: servicio | D1: etapa_funcional | E1: sub_etapa_funcional | F1: rubro | G1: monto_aprobado
A2: CNEL EP UN Bolívar | B2: 2026 | C2: SPEE | D2: Subtransmisión | E2: Lineas de Subtransmisión | F2: AOMC | G2: 936346.8
A3: CNEL EP UN El Oro | B3: 2026 | C3: SPEE | D3: Subtransmisión | E3: Lineas de Subtransmisión | F3: AOMC | G3: 1835700.4
A4: CNEL EP UN Esmeraldas | B4: 2026 | C4: SPEE | D4: Subtransmisión | E4: Lineas de Subtransmisión | F4: AOMC | G4: 2711906.5
A5: CNEL EP UN Guayaquil | B5: 2026 | C5: SPEE | D5: Subtransmisión | E5: Lineas de Subtransmisión | F5: AOMC | G5: 5356646.3
A6: CNEL EP UN Guayas Los Ríos | B6: 2026 | C6: SPEE | D6: Subtransmisión | E6: Lineas de Subtransmisión | F6: AOMC | G6: 7685263.5
A7: CNEL EP UN Los Ríos | B7: 2026 | C7: SPEE | D7: Subtransmisión | E7: Lineas de Subtransmisión | F7: AOMC | G7: 1675490.3
A8: CNEL EP UN Manabí | B8: 2026 | C8: SPEE | D8: Subtransmisión | E8: Lineas de Subtransmisión | F8: AOMC | G8: 11266552
A9: CNEL EP UN Milagro | B9: 2026 | C9: SPEE | D9: Subtransmisión | E9: Lineas de Subtransmisión | F9: AOMC | G9: 2234549.7
A10: CNEL EP UN Santa Elena | B10: 2026 | C10: SPEE | D10: Subtransmisión | E10: Lineas de Subtransmisión | F10: AOMC | G10: 2641097.7
A11: CNEL EP UN Santo Domingo | B11: 2026 | C11: SPEE | D11: Subtransmisión | E11: Lineas de Subtransmisión | F11: AOMC | G11: 1244672.3
A12: CNEL EP UN Sucumbíos | B12: 2026 | C12: SPEE | D12: Subtransmisión | E12: Lineas de Subtransmisión | F12: AOMC | G12: 1037213.3
A13: EE Ambato | B13: 2026 | C13: SPEE | D13: Subtransmisión | E13: Lineas de Subtransmisión | F13: AOMC | G13: 526225.8
... A181: CNEL EP UN Sucumbíos | B181: 2026 | C181: SAPG | D181: AOM | E181: Operación y Mantenimiento | F181: AOM | G181: 832273

Sheet FORM RESUMEN 
B1: AGENCIA DE REGULACIÓN Y CONTROL DE ELECTRICIDAD - ARCONEL
B2: RESUMEN DE EJECUCIÓN PRESUPUESTARIA
B3: PERÍODO: Enero a diciembre 2026
B5: Empresa Distribuidora: | D5: CNEL EP Eficiencia Energética
B7: Con corte a: | D7: Al 31 de diciembre de 2026 - Preliminar
B9: Fecha de entrega: | D9: =+VLOOKUP(D7,fechas[],2,FALSE) -> 46402
B11: CONCEPTO | E11: asignacion_inicial | F11: reformas | G11: presupuesto_codificado | H11: pre_compromiso | I11: compromiso | J11: devengado | K11: ejecutado_pagado
B12: PRESUPUESTO DE OPERACIÓN | E12: USD
B13: Ingresos presupuestarios | E13: 0 | F13: 0 | G13: 0 | H13: 0 | I13: 0 | J13: 0 | K13: 0
B14: =+'FORM INGRESOS'!A17 -> Déficit Tarifario | E14: 0 | F14: 0 | G14: 0 | H14: 0 | I14: 0 | J14: 0 | K14: 0
B15: =+'FORM INGRESOS'!A19 -> Subsidios (Informativo) | E15: 0 | F15: 0 | G15: 0 | H15: 0 | I15: 0 | J15: 0 | K15: 0
B16: =+'FORM INGRESOS'!A18 -> Intereses Ganados | E16: 0 | F16: 0 | G16: 0 | H16: 0 | I16: 0 | J16: 0 | K16: 0
B17: =+'FORM INGRESOS'!A20 -> OTROS INGRESOS NO OPERATIVOS | E17: 0 | F17: 0 | G17: 0 | H17: 0 | I17: 0 | J17: 0 | K17: 0
B18: Ingresos presupuestarios neto: | E18: =+E13-E14-E15+E16+E17 -> 0 | F18: =+F13-F14-F15+F16+F17 -> 0 | G18: =+G13-G14-G15+G16+G17 -> 0 | H18: =+H13-H14-H15+H16+H17 -> 0 | I18: =+I13-I14-I15+I16+I17 -> 0 | J18: =+J13-J14-J15+J16+J17 -> 0 | K18: =+K13-K14-K15+K16+K17 -> 0
B19: Costos presupuestarios
B20: Servicio público de energía eléctrica
B21: Costo de energía | E21: 0 | F21: 0 | G21: 0 | H21: 0 | I21: 0 | J21: 0 | K21: 0
B22: Costo de generación | E22: 0 | F22: 0 | G22: 0 | H22: 0 | I22: 0 | J22: 0 | K22: 0
B23: Costos de Red, Comercialización y Administración - AOM&C | E23: 0 | F23: 0 | G23: 0 | H23: 0 | I23: 0 | J23: 0 | K23: 0
B24: Servicio de alumbrado público general
B25: Costo de energía | E25: 0 | F25: 0 | G25: 0 | H25: 0 | I25: 0 | J25: 0 | K25: 0
B26: Costos de Administración, Operación y Mantenimiento | E26: 0 | F26: 0 | G26: 0 | H26: 0 | I26: 0 | J26: 0 | K26: 0
B28: Depreciación, Deterioro y Amortización | E28: 0 | F28: 0 | G28: 0 | H28: 0 | I28: 0 | J28: 0 | K28: 0
B29: Otros gastos no operativos | E29: 0 | F29: 0 | G29: 0 | H29: 0 | I29: 0 | J29: 0 | K29: 0
B30: Costos y gastos presupuestarios: | E30: =SUM(E19:E29) -> 0 | F30: =SUM(F19:F29) -> 0 | G30: =SUM(G19:G29) -> 0 | H30: =SUM(H19:H29) -> 0 | I30: =SUM(I19:I29) -> 0 | J30: =SUM(J19:J29) -> 0 | K30: =SUM(K19:K29) -> 0
B31: Superávit / Déficit presupuestario por uso de recursos propios: | E31: =+E18-E30 -> 0 | F31: =+F18-F30 -> 0 | G31: =+G18-G30 -> 0 | H31: =+H18-H30 -> 0 | I31: =+I18-I30 -> 0 | J31: =+J18-J30 -> 0 | K31: =+K18-K30 -> 0
B32: PRESUPUESTO DE INVERSIÓN
B33: Servicio público de energía eléctrica
B34: Costos de Anualidad del Activo SPEE | E34: 0 | F34: 0 | G34: 0 | H34: 0 | I34: 0 | J34: 0 | K34: 0
B35: Costos de Inversión para Expansión | E35: 0 | F35: 0 | G35: 0 | H35: 0 | I35: 0 | J35: 0 | K35: 0
B37: Servicio de alumbrado público general
B38: Costos de Anualidad del Activo SAPG | E38: 0 | F38: 0 | G38: 0 | H38: 0 | I38: 0 | J38: 0 | K38: 0
B39: Costos de Expansión | E39: 0 | F39: 0 | G39: 0 | H39: 0 | I39: 0 | J39: 0 | K39: 0
B40: Otros Programas y/o Proyectos (Uso del recurso de la tarifa, No Estudios de Costos)
B41: Otros Programas y/o Proyectos SPEE (Uso del recurso de la tarifa) | E41: 0 | F41: 0 | G41: 0 | H41: 0 | I41: 0 | J41: 0 | K41: 0
B42: Otros Programas y/o Proyectos SAPG (Uso del recurso de la tarifa) | E42: 0 | F42: 0 | G42: 0 | H42: 0 | I42: 0 | J42: 0 | K42: 0
B44: Presupuesto General del Estado y otros financiamientos
B45: Proyectos financiados con Organismos multilaterales y Aporte Local SPEE | E45: 0 | F45: 0 | G45: 0 | H45: 0 | I45: 0 | J45: 0 | K45: 0
B46: Proyectos financiados con Organismos multilaterales y Aporte Local SAPG | E46: 0 | F46: 0 | G46: 0 | H46: 0 | I46: 0 | J46: 0 | K46: 0
B47: Proyectos de Generación | E47: 0 | F47: 0 | G47: 0 | H47: 0 | I47: 0 | J47: 0 | K47: 0
...

Sheet FORM 1 GASTO AO&M-C SPEE
A1: subetapafuncional | C1: etapa_funcional | E1: aprobado | F1: asignacion_inicial | G1: reformas | H1: presupuesto_codificado | I1: pre_compromiso | J1: compromiso | K1: devengado | L1: pagado
A2: Lineas de Subtransmisión | C2: Subtransmisión | D2: Red | E2: {=+SUMIFS('Recursos aprobados'!G:G,'Recursos aprobados'!A:A,'FORM RESUMEN '!$D$5,'Recursos aprobados'!F:F,"AOMC",'Recursos aprobados'!E:E,'FORM 1 GASTO AO&M-C SPEE'!A2:A2)} -> 0 | F2: 0 | G2: 0 | H2: 0 | I2: 0 | J2: 0 | K2: 0 | L2: 0
A3: S/E de Distribución | E3: {=+SUMIFS('Recursos aprobados'!G:G,'Recursos aprobados'!A:A,'FORM RESUMEN '!$D$5,'Recursos aprobados'!F:F,"AOMC",'Recursos aprobados'!E:E,'FORM 1 GASTO AO&M-C SPEE'!A3:A3)} -> 0 | F3: 0 | G3: 0 | H3: 0 | I3: 0 | J3: 0 | K3: 0 | L3: 0
A4: Alimentadores Primarios | C4: Distribución | E4: {=+SUMIFS('Recursos aprobados'!G:G,'Recursos aprobados'!A:A,'FORM RESUMEN '!$D$5,'Recursos aprobados'!F:F,"AOMC",'Recursos aprobados'!E:E,'FORM 1 GASTO AO&M-C SPEE'!A4:A4)} -> 0 | F4: 0 | G4: 0 | H4: 0 | I4: 0 | J4: 0 | K4: 0 | L4: 0
A5: Transformadores de Distribución | E5: {=+SUMIFS('Recursos aprobados'!G:G,'Recursos aprobados'!A:A,'FORM RESUMEN '!$D$5,'Recursos aprobados'!F:F,"AOMC",'Recursos aprobados'!E:E,'FORM 1 GASTO AO&M-C SPEE'!A5:A5)} -> 0 | F5: 0 | G5: 0 | H5: 0 | I5: 0 | J5: 0 | K5: 0 | L5: 0
A6: Red Secundaria | E6: {=+SUMIFS('Recursos aprobados'!G:G,'Recursos aprobados'!A:A,'FORM RESUMEN '!$D$5,'Recursos aprobados'!F:F,"AOMC",'Recursos aprobados'!E:E,'FORM 1 GASTO AO&M-C SPEE'!A6:A6)} -> 0 | F6: 0 | G6: 0 | H6: 0 | I6: 0 | J6: 0 | K6: 0 | L6: 0
A7: Acometidas y Medidores | C7: Instalaciones de Servicio al Cliente | E7: {=+SUMIFS('Recursos aprobados'!G:G,'Recursos aprobados'!A:A,'FORM RESUMEN '!$D$5,'Recursos aprobados'!F:F,"AOMC",'Recursos aprobados'!E:E,'FORM 1 GASTO AO&M-C SPEE'!A7:A7)} -> 0 | F7: 0 | G7: 0 | H7: 0 | I7: 0 | J7: 0 | K7: 0 | L7: 0
A8: Comercialización | C8: Comercialización | D8: Comercialización | E8: {=+SUMIFS('Recursos aprobados'!G:G,'Recursos aprobados'!A:A,'FORM RESUMEN '!$D$5,'Recursos aprobados'!F:F,"AOMC",'Recursos aprobados'!E:E,'FORM 1 GASTO AO&M-C SPEE'!A8:A8)} -> 0 | F8: 0 | G8: 0 | H8: 0 | I8: 0 | J8: 0 | K8: 0 | L8: 0
A9: Administración | C9: Administración | D9: Administración | E9: {=+SUMIFS('Recursos aprobados'!G:G,'Recursos aprobados'!A:A,'FORM RESUMEN '!$D$5,'Recursos aprobados'!F:F,"AOMC",'Recursos aprobados'!E:E,'FORM 1 GASTO AO&M-C SPEE'!A9:A9)} -> 0 | F9: 0 | G9: 0 | H9: 0 | I9: 0 | J9: 0 | K9: 0 | L9: 0
A10: TOTALES | E10: =SUM(E2:E9) -> 0 | F10: =SUM(F2:F9) -> 0 | G10: =SUM(G2:G9) -> 0 | H10: =SUM(H2:H9) -> 0 | I10: =SUM(I2:I9) -> 0 | J10: =SUM(J2:J9) -> 0 | K10: =SUM(K2:K9) -> 0 | L10: =SUM(L2:L9) -> 0
A12: anticipo_no_amortizado | C12: 0 | E12: gestion | I12: sora
A13: total_gasto_AOMC | C13: =+C12+K10 -> 0

Sheet FORM 2 GASTO AO&M-C SPEE
A1: distribuidora | B1: nro_partida | C1: descripcion_partida | D1: etapa_funcional | E1: tipo_gasto | F1: grupo_gasto | G1: asignacion_inicial | H1: reformas | I1: presupuesto_codificado | J1: pre_compromiso | K1: compromiso | L1: devengado | M1: pagado

Sheet FORM 3 ANUALIDAD ACTIVO SPEE
A1: distribuidora | B1: proyecto_arrastre | C1: proyecto_calificado_ecostos | D1: anio_calificacion | E1: codigo_ecostos | F1: rubro_arrastre | G1: codigo_proyecto_eed | H1: nombre_proyecto | I1: objeto_proyecto | J1: provincia | K1: canton | L1: parroquia | M1: aso_transmisión | N1: etapa_funcional | O1: tipo_de_proyecto | P1: estado_proyecto | Q1: etapa_ejecucion_proyecto | R1: avance_ejecucion_fisica | S1: avance_ejecucion_total | T1: fecha_inicio_proyecto | U1: fecha_pro_fin_proyecto | V1: fecha_fin_proyecto | W1: monto_calificado | X1: presupuesto_codificado_arrastre | Y1: devengado_arrastre | Z1: pagado_arrastre | AA1: asignacion_inicial | AB1: reformas | AC1: presupuesto_codificado | AD1: pre_compromiso | AE1: compromiso | AF1: devengado | AG1: pagado | AH1: anticipo_no_amortizado | AI1: bd_planificado | AJ1: bd_ejecutado | AK1: vcs_planificado | AL1: vcs_ejecutado | AM1: vss_planificado | AN1: vss_ejecutado | AO1: tv_planificado | AP1: tv_ejecutado | AQ1: ln_planificado | AR1: ln_ejecutado | AS1: at_planificado | AT1: at_ejecutado | AU1: mt_planificado | AV1: mt_ejecutado | AW1: bt_planificado | AX1: bt_ejecutado | AY1: am_planificado | AZ1: am_ejecutado | BA1: m_planificado | BB1: m_ejecutado | BC1: td_planificado | BD1: td_ejecutado | BE1: pitd_planificado | BF1: pitd_ejecutado | BG1: sdn_planificado | BH1: sdn_ejecutado | BI1: pisdn_planificado | BJ1: pisdn_ejecutado | BK1: perm_amb | BL1: fecha_perm_amb_planif | BM1: fecha_perm_amb_ejec | BN1: empleos_generados | BO1: nro_personal_fem | BP1: observaciones

Sheet FORM 4 EXPANSION SPEE
A1: distribuidora | B1: proyecto_arrastre | C1: anio_calificacion | D1: codigo_proyecto_eed | E1: nombre_proyecto | F1: objeto_proyecto | G1: provincia | H1: canton | I1: parroquia | J1: aso_transmisión | K1: etapa_funcional | L1: estado_proyecto | M1: etapa_ejecucion_proyecto | N1: avance_ejecucion_fisica | O1: avance_ejecucion_total | P1: fecha_inicio_proyecto | Q1: fecha_pro_fin_proyecto | R1: fecha_fin_proyecto | S1: presupuesto_codificado_arrastre | T1: devengado_arrastre | U1: pagado_arrastre | V1: asignacion_inicial | W1: reformas | X1: presupuesto_codificado | Y1: pre_compromiso | Z1: compromiso | AA1: devengado | AB1: pagado | AC1: anticipo_no_amortizado | AD1: bd_planificado | AE1: bd_ejecutado | AF1: vcs_planificado | AG1: vcs_ejecutado | AH1: vss_planificado | AI1: vss_ejecutado | AJ1: tv_planificado | AK1: tv_ejecutado | AL1: ln_planificado | AM1: ln_ejecutado | AN1: at_planificado | AO1: at_ejecutado | AP1: mt_planificado | AQ1: mt_ejecutado | AR1: bt_planificado | AS1: bt_ejecutado | AT1: am_planificado | AU1: am_ejecutado | AV1: m_planificado | AW1: m_ejecutado | AX1: td_planificado | AY1: td_ejecutado | AZ1: pitd_planificado | BA1: pitd_ejecutado | BB1: sdn_planificado | BC1: sdn_ejecutado | BD1: pisdn_planificado | BE1: pisdn_ejecutado | BF1: perm_amb | BG1: fecha_permiso_planif | BH1: fecha_permiso_ejec | BI1: empleos_generados | BJ1: nro_personal_fem | BK1: observaciones
O2: =+IF($M2="No iniciado 0%",0%,IF($M2="Elaboración de pliegos 5%",5%,IF($M2="Disponibilidad de pliegos 10%",10%,IF($M2="Publicación del proceso 15%",15%,IF($M2="Resolución de adjudicación 30%",30%,IF($M2="Adjudicación y firma de contrato 40%",40%,IF($M2="En ejecución 41% - 90%",(40%+($N2*50%)),IF($M2="Acta de entrega - recepción 95%",IF($N2=100%,95%,""),IF($M2="Registro contable 100%",IF($N2=100%,100%,""),"")))))))))

Sheet FORM 5 GASTO AO&M SAPG
A1: ETAPA FUNCIONAL | B1: aprobado | C1: asignacion_inicial | D1: reformas | E1: presupuesto_codificado | F1: pre_compromiso | G1: compromiso | H1: devengado | I1: pagado
A2: Operación y Mantenimiento | B2: =+SUMIFS(recursos_aprobados[monto_aprobado],recursos_aprobados[servicio],"SAPG",recursos_aprobados[distribuidora],'FORM RESUMEN '!D5) -> 0 | C2: 0 | D2: 0 | E2: 0 | F2: 0 | G2: 0 | H2: 0 | I2: 0
A3: Administración | C3: 0 | D3: 0 | E3: 0 | F3: 0 | G3: 0 | H3: 0 | I3: 0
A4: TOTALES | B4: =SUM(B2) -> 0 | C4: =SUM(C2:C3) -> 0 | D4: =SUM(D2:D3) -> 0 | E4: =SUM(E2:E3) -> 0 | F4: =SUM(F2:F3) -> 0 | G4: =SUM(G2:G3) -> 0 | H4: =SUM(H2:H3) -> 0 | I4: =SUM(I2:I3) -> 0
A6: anticipo_no_amortizado | B6: 0
A7: total_gasto_AOM | B7: =+B6+H4 -> 0

Sheet FORM 6 GASTO AO&M SAPG
A1: distribuidora | B1: nro_partida | C1: descripcion_partida | D1: tipo_gasto | E1: grupo_gasto | F1: asignacion_inicial | G1: reformas | H1: presupuesto_codificado | I1: pre_compromiso | J1: compromiso | K1: devengado | L1: pagado

Sheet FORM 7 ANUALIDAD ACTIVO SAPG
A1: distribuidora | B1: proyecto_arrastre | C1: proyecto_calificado_ecostos | D1: anio_calificacion | E1: codigo_ecostos | F1: rubro_arrastre | G1: codigo_proyecto_eed | H1: nombre_proyecto | I1: objeto_proyecto | J1: provincia | K1: canton | L1: parroquia | M1: estado_proyecto | N1: etapa_ejecucion_proyecto | O1: avance_ejecucion_fisica | P1: avance_ejecucion_total | Q1: fecha_inicio_proyecto | R1: fecha_pro_fin_proyecto | S1: fecha_fin_proyecto | T1: monto_calificado | U1: presupuesto_codificado_arrastre | V1: devengado_arrastre | W1: pagado_arrastre | X1: asignacion_inicial | Y1: reformas | Z1: presupuesto_codificado | AA1: pre_compromiso | AB1: compromiso | AC1: devengado | AD1: pagado | AE1: anticipo_no_amortizado | AF1: Ln_inst_tipo | AG1: Ln_inst_potencia | AH1: Ln_inst_cantidad | AI1: Ln_reemp_tipo | AJ1: Ln_reemp_potencia | AK1: Ln_reemp_cantidad | AL1: Lumin_inst_total | AM1: Postes_nuev_número | AN1: Postes_reemp_número | AO1: Benef_dir_número | AP1: empleos_generados | AQ1: nro_personal_fem | AR1: observaciones
P2: =+IF($N2="No iniciado 0%",0%,IF($O2="Elaboración de pliegos 5%",5%,IF($N2="Disponibilidad de pliegos 10%",10%,IF($N2="Publicación del proceso 15%",15%,IF($N2="Resolución de adjudicación 30%",30%,IF($N2="Adjudicación y firma de contrato 40%",40%,IF($N2="En ejecución 41% - 90%",(40%+($O2*50%)),IF($N2="Acta de entrega - recepción 95%",IF($O2=100%,95%,""),IF($N2="Registro contable 100%",IF($O2=100%,100%,""),"")))))))))

Sheet FORM 8 EXPANSION SAPG
A1: distribuidora | B1: proyecto_arrastre | C1: anio_calificacion | D1: codigo_proyecto_eed | E1: nombre_proyecto | F1: objeto_proyecto | G1: provincia | H1: canton | I1: parroquia | J1: estado_proyecto | K1: etapa_ejecucion_proyecto | L1: avance_ejecucion_fisica | M1: avance_ejecucion_total | N1: fecha_inicio_proyecto | O1: fecha_pro_fin_proyecto | P1: fecha_fin_proyecto | Q1: presupuesto_codificado_arrastre | R1: devengado_arrastre | S1: pagado_arrastre | T1: asignacion_inicial | U1: reformas | V1: presupuesto_codificado | W1: pre_compromiso | X1: compromiso | Y1: devengado | Z1: pagado | AA1: anticipo_no_amortizado | AB1: Ln_inst_tipo | AC1: Ln_inst_potencia | AD1: Ln_inst_cantidad | AE1: Ln_reemp_tipo | AF1: Ln_reemp_potencia | AG1: Ln_reemp_cantidad | AH1: Lumin_inst_total | AI1: Postes_nuev_número | AJ1: Postes_reemp_número | AK1: Benef_dir_número | AL1: empleos_generados | AM1: nro_personal_fem | AN1: observaciones
M2: =+IF($K2="No iniciado 0%",0%,IF($K2="Elaboración de pliegos 5%",5%,IF($K2="Disponibilidad de pliegos 10%",10%,IF($K2="Publicación del proceso 15%",15%,IF($K2="Resolución de adjudicación 30%",30%,IF($K2="Adjudicación y firma de contrato 40%",40%,IF($K2="En ejecución 41% - 90%",(40%+($L2*50%)),IF($K2="Acta de entrega - recepción 95%",IF($L2=100%,95%,""),IF($K2="Registro contable 100%",IF($L2=100%,100%,""),"")))))))))

Sheet FORM 9 OTROS RECURSOS
A1: distribuidora | B1: fuente | C1: proyecto_arrastre | D1: servicio | E1: codigo_proyecto_eed | F1: nombre_proyecto | G1: objeto_proyecto | H1: provincia | I1: canton | J1: parroquia | K1: estado_proyecto | L1: etapa_ejecucion_proyecto | M1: avance_ejecucion_fisica | N1: avance_ejecucion_total | O1: fecha_inicio_proyecto | P1: fecha_pro_fin_proyecto | Q1: fecha_fin_proyecto | R1: presupuesto_codificado_arrastre | S1: devengado_arrastre | T1: pagado_arrastre | U1: asignacion_inicial | V1: reformas | W1: presupuesto_codificado | X1: pre_compromiso | Y1: compromiso | Z1: devengado | AA1: pagado | AB1: anticipo_no_amortizado | AC1: observaciones
N2: =+IF($L2="No iniciado 0%",0%,IF($L2="Elaboración de pliegos 5%",5%,IF($L2="Disponibilidad de pliegos 10%",10%,IF($L2="Publicación del proceso 15%",15%,IF($L2="Resolución de adjudicación 30%",30%,IF($L2="Adjudicación y firma de contrato 40%",40%,IF($L2="En ejecución 41% - 90%",(40%+($M2*50%)),IF($L2="Acta de entrega - recepción 95%",IF($M2=100%,95%,""),IF($L2="Registro contable 100%",IF($M2=100%,100%,""),"")))))))))

Sheet FORM INGRESOS
A1: INGRESOS PRESUPUESTARIOS | B1: Asignación inicial (USD) | C1: Reformas (USD) | D1: Monto Codificado (USD) | E1: Pre-Compromiso (USD) | F1: Compromiso (USD) | G1: Devengado (USD) | H1: Recaudado (USD)
A2: INGRESOS DE ACTIVIDADES ORDINARIAS (Operación)
A3: Ventas | B3: =+B4+B12+B14 -> 0 | C3: =+C4+C12+C14 -> 0 | D3: =+D4+D12+D14 -> 0 | E3: =+E4+E12+E14 -> 0 | F3: =+F4+F12+F14 -> 0 | G3: =+G4+G12+G14 -> 0 | H3: =+H4+H12+H14 -> 0
A4: Venta de Energía con Tarifa 0% | B4: =+B5+B10+B11 -> 0 | C4: =+C5+C10+C11 -> 0 | D4: =+D5+D10+D11 -> 0 | E4: =+E5+E10+E11 -> 0 | F4: =+F5+F10+F11 -> 0 | G4: =+G5+G10+G11 -> 0 | H4: =+H5+H10+H11 -> 0
A5: Venta de Energía Consumidores | B5: =+B6+B7+B8+B9 -> 0 | C5: =+C6+C7+C8+C9 -> 0 | D5: =+D6+D7+D8+D9 -> 0 | E5: =+E6+E7+E8+E9 -> 0 | F5: =+F6+F7+F8+F9 -> 0 | G5: =+G6+G7+G8+G9 -> 0 | H5: =+H6+H7+H8+H9 -> 0
A6: Residencial
A7: Comercial
A8: Industrial
A9: Otras
A10: Venta de Energía Generada
A11: Venta de Energía de Sistema de Alumbrado Público
A12: Otras Ventas Tarifa 0% | B12: =+B13 -> 0 | C12: =+C13 -> 0 | D12: =+D13 -> 0 | E12: =+E13 -> 0 | F12: =+F13 -> 0 | G12: =+G13 -> 0 | H12: =+H13 -> 0
A13: Otras Ventas con Tarifa 0% Relacionado a la Venta Energía
A14: Ventas con Tarifa 15% | B14: =+SUM(B15:B16) -> 0 | C14: =+SUM(C15:C16) -> 0 | D14: =+SUM(D15:D16) -> 0 | E14: =+SUM(E15:E16) -> 0 | F14: =+SUM(F15:F16) -> 0 | G14: =+SUM(G15:G16) -> 0 | H14: =+SUM(H15:H16) -> 0
A15: Ingresos por Venta de Bienes y Servicios relacionados con la Energía
A16: Ingresos por Venta de Bienes y Servicios no relacionados con la Energía
A17: Déficit Tarifario
A18: Intereses Ganados
A19: Subsidios (Informativo)
A20: OTROS INGRESOS NO OPERATIVOS | B20: =+B21 -> 0 | C20: =+C21 -> 0 | D20: =+D21 -> 0 | E20: =+E21 -> 0 | F20: =+F21 -> 0 | G20: =+G21 -> 0 | H20: =+H21 -> 0
A21: Otros ingresos no operativos
A22: TOTAL INGRESOS: | B22: =+B3+B17+B19+B18+B20 -> 0 | C22: =+C3+C17+C19+C18+C20 -> 0 | D22: =+D3+D17+D19+D18+D20 -> 0 | E22: =+E3+E17+E19+E18+E20 -> 0 | F22: =+F3+F17+F19+F18+F20 -> 0 | G22: =+G3+G17+G19+G18+G20 -> 0 | H22: =+H3+H17+H19+H18+H20 -> 0
A24: Cuentas por cobrar (Informativo)

Sheet FORM EGRESOS
A1: COMPONENTES | B1: Asignación inicial (USD) | C1: Reformas (USD) | D1: Codificado (USD) | E1: Pre-Compromiso (USD) | F1: Compromiso (USD) | G1: Devengado (USD) | H1: Pagado (USD)
A2: Servicio público de energía eléctrica
A3: Costo de energía
A4: COSTO DE DISTRIBUCIÓN Y COMERCIALIZACIÓN | B4: =SUM(B3) -> 0 | C4: =SUM(C3) -> 0 | D4: =SUM(D3) -> 0 | E4: =SUM(E3) -> 0 | F4: =SUM(F3) -> 0 | G4: =SUM(G3) -> 0 | H4: =SUM(H3) -> 0
A5: Costos de Red, Comercialización y Administración - AOM&C
A6: Costos de Anualidad del Activo SPEE
A7: Costos de Inversión para Expansión
A8: Total: | B8: =SUM(B5:B7) -> 0 | C8: =SUM(C5:C7) -> 0 | D8: =SUM(D5:D7) -> 0 | E8: =SUM(E5:E7) -> 0 | F8: =SUM(F5:F7) -> 0 | G8: =SUM(G5:G7) -> 0 | H8: =SUM(H5:H7) -> 0
A9: Servicio de alumbrado público general
A10: Costo de energía
A11: PLAN DE ALUMBRADO PÚBLICO | B11: =SUM(B10) -> 0 | C11: =SUM(C10) -> 0 | D11: =SUM(D10) -> 0 | E11: =SUM(E10) -> 0 | F11: =SUM(F10) -> 0 | G11: =SUM(G10) -> 0 | H11: =SUM(H10) -> 0
A12: Costos de Administración, Operación y Mantenimiento
A13: Costos de Anualidad del Activo SAPG
A14: Costos de Expansión
A15: Total: | B15: =SUM(B12:B14) -> 0 | C15: =SUM(C12:C14) -> 0 | D15: =SUM(D12:D14) -> 0 | E15: =SUM(E12:E14) -> 0 | F15: =SUM(F12:F14) -> 0 | G15: =SUM(G12:G14) -> 0 | H15: =SUM(H12:H14) -> 0
A16: Otros Programas y/o Proyectos (Uso del recurso de la tarifa, No Estudios de Costos)
A17: Otros Programas y/o Proyectos SPEE (Uso del recurso de la tarifa)
A18: Otros Programas y/o Proyectos SAPG (Uso del recurso de la tarifa)
A20: Presupuesto General del Estado
A21: Proyectos financiados con Organismos multilaterales y Aporte Local de SPEE
A22: Proyectos financiados con Organismos multilaterales y Aporte Local de SAPG
A24: Costos de Generación
A25: Proyectos Generación
A26: Gastos de depreciación de propiedad, planta y equipo, deterioro y baja de propiedad, planta y equipo, deterioro de otros activos y amortización
A27: Otros gastos no operativos
A28: TOTAL EGRESOS PRESUPUESTARIOS: | B28: =+B4+B8+B11+B15+B17+B18+B21+B22+B24+B25+B27 -> 0 | C28: =+C4+C8+C11+C15+C17+C18+C21+C22+C24+C25+C27 -> 0 | D28: =+D4+D8+D11+D15+D17+D18+D21+D22+D24+D25+D27 -> 0 | E28: =+E4+E8+E11+E15+E17+E18+E21+E22+E24+E25+E27 -> 0 | F28: =+F4+F8+F11+F15+F17+F18+F21+F22+F24+F25+F27 -> 0 | G28: =+G4+G8+G11+G15+G17+G18+G21+G22+G24+G25+G27 -> 0 | H28: =+H4+H8+H11+H15+H17+H18+H21+H22+H24+H25+H27 -> 0
A30: Cuentas por pagar (Informativo)

Sheet FLUJO DE CAJA
A1: CONCEPTO | B1: SALDOS A 31 12 2025 | C1: 2026
C2: ENERO | D2: FEBRERO | E2: MARZO | F2: ABRIL | G2: MAYO | H2: JUNIO | I2: JULIO | J2: AGOSTO | K2: SEPTIEMBRE | L2: OCTUBRE | M2: NOVIEMBRE | N2: DICIEMBRE | O2: ACUMULADO
A3: SALDO INICIAL DE EFECTIVO
A4: ENTRADAS DE EFECTIVO | B4: =+B5+B11+B25+B36+B41+B42 -> 0 | C4: =+C5+C11+C25+C36+C41+C42 -> 0 | D4: =+D5+D11+D25+D36+D41+D42 -> 0 | E4: =+E5+E11+E25+E36+E41+E42 -> 0 | F4: =+F5+F11+F25+F36+F41+F42 -> 0 | G4: =+G5+G11+G25+G36+G41+G42 -> 0 | H4: =+H5+H11+H25+H36+H41+H42 -> 0 | I4: =+I5+I11+I25+I36+I41+I42 -> 0 | ... O4: =+O5+O11+O25+O36+O41+O42 -> 0
A5: 1.-Ingresos de Operación | B5: =SUM(B6:B9) -> 0 | C5: =SUM(C6:C9) -> 0 | D5: =SUM(D6:D9) -> 0 | E5: =SUM(E6:E9) -> 0 | F5: =SUM(F6:F9) -> 0 | G5: =SUM(G6:G9) -> 0 | H5: =SUM(H6:H9) -> 0 | I5: =SUM(I6:I9) -> 0 | ... O5: =SUM(O6:O9) -> 0
A6: Venta de Energia Consumidores | B6: 0 | C6: 0 | D6: 0 | E6: 0 | F6: 0 | G6: 0 | H6: 0 | I6: 0 | J6: 0 | K6: 0 | L6: 0 | M6: 0 | N6: 0 | O6: 0
A7: Venta de Energía Generada | B7: 0 | C7: 0 | D7: 0 | E7: 0 | F7: 0 | G7: 0 | H7: 0 | I7: 0 | J7: 0 | K7: 0 | L7: 0 | M7: 0 | N7: 0 | O7: 0
A8: Venta de Energía Sistema de Alumbrado Público | B8: 0 | C8: 0 | D8: 0 | E8: 0 | F8: 0 | G8: 0 | H8: 0 | I8: 0 | J8: 0 | K8: 0 | L8: 0 | M8: 0 | N8: 0 | O8: 0
A9: Ingresos que no son Venta de Energía | B9: 0 | C9: 0 | D9: 0 | E9: 0 | F9: 0 | G9: 0 | H9: 0 | I9: 0 | J9: 0 | K9: 0 | L9: 0 | M9: 0 | N9: 0 | O9: 0
A10: Subsidios (Recaudación real)
A11: 2.-Recursos para Inversión Programas de Crédito | B11: =SUM(B12:B24) -> 0 | C11: =SUM(C12:C24) -> 0 | D11: =SUM(D12:D24) -> 0 | E11: =SUM(E12:E24) -> 0 | F11: =SUM(F12:F24) -> 0 | G11: =SUM(G12:G24) -> 0 | H11: =SUM(H12:H24) -> 0 | I11: =SUM(I12:I24) -> 0 | ... O11: =SUM(O12:O24) -> 0
A12: PLANREP Crédito | B12: 0 | C12: 0 | D12: 0 | E12: 0 | F12: 0 | G12: 0 | H12: 0 | I12: 0 | J12: 0 | K12: 0 | L12: 0 | M12: 0 | N12: 0 | O12: 0
A13: PMD Crédito | B13: 0 | C13: 0 | D13: 0 | E13: 0 | F13: 0 | G13: 0 | H13: 0 | I13: 0 | J13: 0 | K13: 0 | L13: 0 | M13: 0 | N13: 0 | O13: 0
A14: PMD BID I | B14: 0 | C14: 0 | D14: 0 | E14: 0 | F14: 0 | G14: 0 | H14: 0 | I14: 0 | J14: 0 | K14: 0 | L14: 0 | M14: 0 | N14: 0 | O14: 0
A15: PMD BID II | B15: 0 | C15: 0 | D15: 0 | E15: 0 | F15: 0 | G15: 0 | H15: 0 | I15: 0 | J15: 0 | K15: 0 | L15: 0 | M15: 0 | N15: 0 | O15: 0
A16: PMD BID III | B16: 0 | C16: 0 | D16: 0 | E16: 0 | F16: 0 | G16: 0 | H16: 0 | I16: 0 | J16: 0 | K16: 0 | L16: 0 | M16: 0 | N16: 0 | O16: 0
A17: PMD CAF | B17: 0 | C17: 0 | D17: 0 | E17: 0 | F17: 0 | G17: 0 | H17: 0 | I17: 0 | J17: 0 | K17: 0 | L17: 0 | M17: 0 | N17: 0 | O17: 0
A18: PMD AFD | B18: 0 | C18: 0 | D18: 0 | E18: 0 | F18: 0 | G18: 0 | H18: 0 | I18: 0 | J18: 0 | K18: 0 | L18: 0 | M18: 0 | N18: 0 | O18: 0
A19: PMD BID V | B19: 0 | C19: 0 | D19: 0 | E19: 0 | F19: 0 | G19: 0 | H19: 0 | I19: 0 | J19: 0 | K19: 0 | L19: 0 | M19: 0 | N19: 0 | O19: 0
A20: FERUM | B20: 0 | C20: 0 | D20: 0 | E20: 0 | F20: 0 | G20: 0 | H20: 0 | I20: 0 | J20: 0 | K20: 0 | L20: 0 | M20: 0 | N20: 0 | O20: 0
A21: FERUM BID II | B21: 0 | C21: 0 | D21: 0 | E21: 0 | F21: 0 | G21: 0 | H21: 0 | I21: 0 | J21: 0 | K21: 0 | L21: 0 | M21: 0 | N21: 0 | O21: 0
A22: FERUM BID III | B22: 0 | C22: 0 | D22: 0 | E22: 0 | F22: 0 | G22: 0 | H22: 0 | I22: 0 | J22: 0 | K22: 0 | L22: 0 | M22: 0 | N22: 0 | O22: 0
A23: FERUM BID V | B23: 0 | C23: 0 | D23: 0 | E23: 0 | F23: 0 | G23: 0 | H23: 0 | I23: 0 | J23: 0 | K23: 0 | L23: 0 | M23: 0 | N23: 0 | O23: 0
A24: PRIZA | B24: 0 | C24: 0 | D24: 0 | E24: 0 | F24: 0 | G24: 0 | H24: 0 | I24: 0 | J24: 0 | K24: 0 | L24: 0 | M24: 0 | N24: 0 | O24: 0
A25: 3.-Recursos Fiscales | B25: =SUM(B26:B35) -> 0 | C25: =SUM(C26:C35) -> 0 | D25: =SUM(D26:D35) -> 0 | E25: =SUM(E26:E35) -> 0 | F25: =SUM(F26:F35) -> 0 | G25: =SUM(G26:G35) -> 0 | H25: =SUM(H26:H35) -> 0 | I25: =SUM(I26:I35) -> 0 | ... O25: =SUM(O26:O35) -> 0
A26: PMD Fiscales | B26: 0 | C26: 0 | D26: 0 | E26: 0 | F26: 0 | G26: 0 | H26: 0 | I26: 0 | J26: 0 | K26: 0 | L26: 0 | M26: 0 | N26: 0 | O26: 0
A27: FERUM Fiscales | B27: 0 | C27: 0 | D27: 0 | E27: 0 | F27: 0 | G27: 0 | H27: 0 | I27: 0 | J27: 0 | K27: 0 | L27: 0 | M27: 0 | N27: 0 | O27: 0
A28: BID I | B28: 0 | C28: 0 | D28: 0 | E28: 0 | F28: 0 | G28: 0 | H28: 0 | I28: 0 | J28: 0 | K28: 0 | L28: 0 | M28: 0 | N28: 0 | O28: 0
A29: BID II | B29: 0 | C29: 0 | D29: 0 | E29: 0 | F29: 0 | G29: 0 | H29: 0 | I29: 0 | J29: 0 | K29: 0 | L29: 0 | M29: 0 | N29: 0 | O29: 0
A30: BIDIII | B30: 0 | C30: 0 | D30: 0 | E30: 0 | F30: 0 | G30: 0 | H30: 0 | I30: 0 | J30: 0 | K30: 0 | L30: 0 | M30: 0 | N30: 0 | O30: 0
A31: BID IV | B31: 0 | C31: 0 | D31: 0 | E31: 0 | F31: 0 | G31: 0 | H31: 0 | I31: 0 | J31: 0 | K31: 0 | L31: 0 | M31: 0 | N31: 0 | O31: 0
A32: BID V | B32: 0 | C32: 0 | D32: 0 | E32: 0 | F32: 0 | G32: 0 | H32: 0 | I32: 0 | J32: 0 | K32: 0 | L32: 0 | M32: 0 | N32: 0 | O32: 0
A33: BID VI | B33: 0 | C33: 0 | D33: 0 | E33: 0 | F33: 0 | G33: 0 | H33: 0 | I33: 0 | J33: 0 | K33: 0 | L33: 0 | M33: 0 | N33: 0 | O33: 0
A34: PRIZA | B34: 0 | C34: 0 | D34: 0 | E34: 0 | F34: 0 | G34: 0 | H34: 0 | I34: 0 | J34: 0 | K34: 0 | L34: 0 | M34: 0 | N34: 0 | O34: 0
A35: Subsidios ( cuentas por cobrar) | B35: 0 | C35: 0 | D35: 0 | E35: 0 | F35: 0 | G35: 0 | H35: 0 | I35: 0 | J35: 0 | K35: 0 | L35: 0 | M35: 0 | N35: 0 | O35: 0
A36: 4.-Otros Ingresos de Efectivo | B36: =SUM(B37:B40) -> 0 | C36: =SUM(C37:C40) -> 0 | D36: =SUM(D37:D40) -> 0 | E36: =SUM(E37:E40) -> 0 | F36: =SUM(F37:F40) -> 0 | G36: =SUM(G37:G40) -> 0 | H36: =SUM(H37:H40) -> 0 | I36: =SUM(I37:I40) -> 0 | ... O36: =SUM(O37:O40) -> 0
A37: Otras Inversiones y Convenios | B37: 0 | C37: 0 | D37: 0 | E37: 0 | F37: 0 | G37: 0 | H37: 0 | I37: 0 | J37: 0 | K37: 0 | L37: 0 | M37: 0 | N37: 0 | O37: 0
A38: Aportes de Otros Accionistas | B38: 0 | C38: 0 | D38: 0 | E38: 0 | F38: 0 | G38: 0 | H38: 0 | I38: 0 | J38: 0 | K38: 0 | L38: 0 | M38: 0 | N38: 0 | O38: 0
A39: Contribuciones de usuarios
A40: Multas a contratistas | B40: 0 | C40: 0 | D40: 0 | E40: 0 | F40: 0 | G40: 0 | H40: 0 | I40: 0 | J40: 0 | K40: 0 | L40: 0 | M40: 0 | N40: 0 | O40: 0
...
